<robot name="myAGV">
  <link name="base_coordinate">
    <visual>
      <geometry>
        <sphere radius="0.001" />
      </geometry>
    </visual>
  </link>

  <link name="base_link">
    <visual>
      <geometry>
        <box size="0.34 0.34 0.34"/>
      </geometry>
      <origin xyz="0 0 0" rpy="0 0 1.57" />
      <material name="blue">
        <color rgba="0 0.25 0.5 0.8" />
      </material>
    </visual>
    <collision>
      <geometry>
        <box size="0.34 0.34 0.34" />
      </geometry>
      <origin xyz="-0.8 0.0 0.0" rpy="0.0 0.0 1.57" />
    </collision>
    <inertial>
      <origin xyz="0 0 0" />
      <mass value="1" />
      <inertia ixx="0.2" ixy="0" ixz="0" iyy="0.2" iyz="0" izz="0.2" />
    </inertial>
  </link>
  <gazebo reference="base_link">
    <material>Gazebo/Blue</material>
  </gazebo>

  <joint name="base_link_to_base_coordinate" type="fixed">
    <parent link="base_coordinate" />
    <child link="base_link"/>
    <origin xyz="0 0 0.205" />
  </joint>



  <link name="right_wheel">
    <visual>
      <geometry>
        <cylinder radius="0.09" length="0.06" />
      </geometry>
      <origin xyz="0 0 0" rpy="1.57 0 0" />
      <material name="black">
        <color rgba="0.0 0.0 0.0 1.0" />
      </material>
    </visual>
    <collision>
      <geometry>
        <cylinder radius="0.09" length="0.06" />
      </geometry>
      <origin xyz="0 0 0" rpy="1.57 0 0" />
    </collision>
    <inertial>
      <origin xyz="0 0 0" />
      <mass value="2" />
      <inertia ixx="0.02" ixy="0" ixz="0" iyy="0.02" iyz="0" izz="0.04" />
    </inertial>
  </link>
  <gazebo reference="right_wheel">
    <material>Gazebo/Black</material>
  </gazebo>

  <joint name="base_r_wheel_joint" type="continuous">
    <parent link="base_link" />
    <child link="right_wheel" />
    <origin xyz="0.13 -0.1575 -0.115" />
    <axis xyz="0 1 0" />
  </joint>


  <link name="left_wheel">
    <visual>
      <geometry>
        <cylinder radius="0.09" length="0.06" />
      </geometry>
      <origin xyz="0 0 0" rpy="1.57 0 0" />
      <material name="black">
        <color rgba="0.0 0.0 0.0 1.0" />
      </material>
    </visual>
    <collision>
      <geometry>
        <cylinder radius="0.09" length="0.06" />
      </geometry>
      <origin xyz="0 0 0" rpy="1.57 0 0" />
    </collision>
    <inertial>
      <origin xyz="0 0 0" />
      <mass value="2" />
      <inertia ixx="0.02" ixy="0" ixz="0" iyy="0.02" iyz="0" izz="0.04" />
    </inertial>
  </link>
  <gazebo reference="left_wheel">
    <material>Gazebo/Black</material>
  </gazebo>

  <joint name="base_l_wheel_joint" type="continuous">
    <parent link="base_link" />
    <child link="left_wheel" />
    <origin xyz="0.13 0.1575 -0.115" />
    <axis xyz="0 1 0" />
  </joint>



  <link name="universal_wheel">
    <visual>
      <geometry>
        <sphere radius="0.035" />
      </geometry>
      <origin xyz="0 0 0" rpy="0 0 0" />
      <material name="black">
        <color rgba="0.0 0.0 0.0 1.0" />
      </material>
    </visual>
    <collision>
      <geometry>
        <sphere radius="0.035" />
      </geometry>
      <origin xyz="0 0 0" rpy="0 0 0" />
    </collision>
    <inertial>
      <origin xyz="0 0 0" />
      <mass value="0.5" />
      <inertia ixx="0.0002" ixy="0" ixz="0" iyy="0.0002" iyz="0" izz="0.0002" />
    </inertial>
  </link>
  <gazebo reference="universal_wheel">
    <material>Gazebo/White</material>
  </gazebo>

  <joint name="universal_wheel_to_base_link" type="continuous">
    <parent link="base_link" />
    <child link="universal_wheel" />
    <origin xyz="-0.135 0 -0.17" />
    <axis xyz="1 1 1" />
  </joint>

  <link name="laser">
    <visual>
      <geometry>
        <box size="0.05 0.05 0.05" />
      </geometry>
      <origin xyz="0 0 0" rpy="0 0 0" />
      <material name="red">
        <color rgba="1.0 0.0 0.0 1.0" />
      </material>
    </visual>
    <collision>
      <geometry>
        <box size="0.05 0.05 0.05" />
      </geometry>
      <origin xyz="0 0 0" rpy="0 0 0" />
    </collision>
    <inertial>
      <origin xyz="0 0 0" />
      <mass value="0.2" />
      <inertia ixx="0.00008" ixy="0" ixz="0" iyy="0.00008" iyz="0" izz="0.00008" />
    </inertial>
  </link>
  <gazebo reference="laser">
    <material>Gazebo/Red</material>
  </gazebo>

  <joint name="laser_to_base_link" type="fixed">
    <parent link="base_link" />
    <child link="laser" />
    <origin xyz="0.12 0 0.195" />
  </joint>


  <link name="camera">
    <visual>
      <geometry>
        <cylinder radius="0.02" length="0.01" />
      </geometry>
      <origin xyz="0 0 0" rpy="0 1.57 0" />
      <material name="yellow">
        <color rgba="1.0 1.0 0.0 1.0" />
      </material>
    </visual>
    <collision>
      <geometry>
        <cylinder radius="0.02" length="0.01" />
      </geometry>
      <origin xyz="0 0 0" rpy="0 1.57 0" />
    </collision>
    <inertial>
      <origin xyz="0 0 0" />
      <mass value="0.1" />
      <inertia ixx="0.00001" ixy="0" ixz="0" iyy="0.00001" iyz="0" izz="0.00002" />
    </inertial>
  </link>
  <gazebo reference="camera">
    <material>Gazebo/Yellow</material>
  </gazebo>

  <joint name="camera_to_base_link" type="fixed">
    <parent link="base_link" />
    <child link="camera" />
    <origin xyz="0.23 0 0.145" />
  </joint>

  <gazebo>
    <plugin name="differential_drive_controller" filename="libgazebo_ros_diff_drive.so">
      <rosDebugLevel>Debug</rosDebugLevel>
      <publishWheelTF>true</publishWheelTF>
      <robotNamespace>/</robotNamespace>
      <publishTf>1</publishTf>
      <publishWheelJointState>true</publishWheelJointState>
      <alwaysOn>true</alwaysOn>
      <updateRate>100.0</updateRate>
      <legacyMode>true</legacyMode>
      <leftJoint>base_l_wheel_joint</leftJoint>
      <rightJoint>base_r_wheel_joint</rightJoint>
      <wheelSeparation>0.315</wheelSeparation>
      <wheelDiameter>0.18</wheelDiameter>
      <broadcastTF>1</broadcastTF>
      <wheelTorque>30</wheelTorque>
      <wheelAcceleration>1.8</wheelAcceleration>
      <commandTopic>cmd_vel</commandTopic>
      <odometryFrame>odom</odometryFrame>
      <odometryTopic>odom</odometryTopic>
      <robotBaseFrame>base_coordinate</robotBaseFrame>
    </plugin>
  </gazebo>

  <gazebo reference="laser">
    <sensor type="ray" name="rplidar">
      <pose>0 0 0 0 0 0</pose>
      <visualize>true</visualize>
      <update_rate>5.5</update_rate>
      <ray>
        <scan>
          <horizontal>
            <samples>360</samples>
            <resolution>1</resolution>
            <min_angle>-3</min_angle>
            <max_angle>3</max_angle>
          </horizontal>
        </scan>
        <range>
          <min>0.10</min>
          <max>30.0</max>
          <resolution>0.01</resolution>
        </range>
        <noise>
          <type>gaussian</type>
          <mean>0.0</mean>
          <stddev>0.01</stddev>
        </noise>
      </ray>
      <plugin name="gazebo_rplidar" filename="libgazebo_ros_laser.so">
        <topicName>/scan</topicName>
        <frameName>laser</frameName>
      </plugin>
    </sensor>
  </gazebo>


</robot>
